This XML file does not appear to have any style information associated with it. The document tree is shown below.
<mujoco model="simple_biped">
<compiler angle="radian" coordinate="local"/>
<option timestep="0.002"/>
<default>
<joint limited="true" damping="1"/>
<geom friction="1 0.5 0.5" density="1000" contype="1" conaffinity="1"/>
</default>
<worldbody>
<!--  Pelvis  -->
<body name="pelvis" pos="0 0 1.0">
<geom name="pelvis_geom" type="box" size="0.15 0.075 0.02" rgba="0.6 0.6 0.6 1"/>
<!--  Left Thigh  -->
<body name="left_thigh" pos="0.05 0 -0.025">
<joint name="left_hip" type="hinge" axis="1 0 0" range="-1.57 1.57"/>
<geom type="box" size="0.025 0.025 0.15" pos="0 0 -0.15"/>
<!--  Left Shin  -->
<body name="left_shin" pos="0 0 -0.3">
<joint name="left_knee" type="hinge" axis="1 0 0" range="-1.57 0"/>
<geom type="box" size="0.02 0.02 0.15" pos="0 0 -0.15"/>
<!--  Left Foot  -->
<body name="left_foot" pos="0 0 -0.3">
<joint name="left_ankle" type="hinge" axis="1 0 0" range="-0.5 0.5"/>
<geom type="box" size="0.04 0.1 0.02" pos="0 0 -0.025"/>
</body>
</body>
</body>
<!--  Right Thigh  -->
<body name="right_thigh" pos="-0.05 0 -0.025">
<joint name="right_hip" type="hinge" axis="1 0 0" range="-1.57 1.57"/>
<geom type="box" size="0.025 0.025 0.15" pos="0 0 -0.15"/>
<!--  Right Shin  -->
<body name="right_shin" pos="0 0 -0.3">
<joint name="right_knee" type="hinge" axis="1 0 0" range="-1.57 0"/>
<geom type="box" size="0.02 0.02 0.15" pos="0 0 -0.15"/>
<!--  Right Foot  -->
<body name="right_foot" pos="0 0 -0.3">
<joint name="right_ankle" type="hinge" axis="1 0 0" range="-0.5 0.5"/>
<geom type="box" size="0.04 0.1 0.02" pos="0 0 -0.025"/>
</body>
</body>
</body>
</body>
</worldbody>
<actuator>
<motor joint="left_hip" ctrlrange="-1 1"/>
<motor joint="left_knee" ctrlrange="-1 1"/>
<motor joint="left_ankle" ctrlrange="-1 1"/>
<motor joint="right_hip" ctrlrange="-1 1"/>
<motor joint="right_knee" ctrlrange="-1 1"/>
<motor joint="right_ankle" ctrlrange="-1 1"/>
</actuator>
</mujoco>